<?xml version="1.0"?>
<robot name="simple_arm">

  <!-- Define materials -->
  <material name="red">
    <color rgba="1 0 0 1"/>
  </material>
  <material name="green">
    <color rgba="0 1 0 1"/>
  </material>
  <material name="white">
    <color rgba="1 1 1 1"/>
  </material>


  <!-- Define links -->
  <link name="base_link"/>

  <link name="link1">
    <visual>
      <origin xyz="0 0 0.25" rpy="0 0 0"/>
      <geometry>
        <capsule length="0.5" radius="0.05"/>
      </geometry>
      <material name="white"/>
    </visual>
    <collision>
     <origin xyz="0 0 0.25" rpy="0 0 0"/>
      <geometry>
        <capsule length="0.5" radius="0.05"/>
      </geometry>
    </collision>
  </link>

  <link name="link2">
    <visual>
     <origin xyz="0 0 0.2" rpy="0 0 0"/>
      <geometry>
        <capsule length="0.4" radius="0.04"/>
      </geometry>
      <material name="white"/>
    </visual>
    <collision>
     <origin xyz="0 0 0.2" rpy="0 0 0"/>
      <geometry>
        <capsule length="0.4" radius="0.04"/>
      </geometry>
    </collision>
  </link>

  <link name="link3">
    <visual>
     <origin xyz="0 0 0.15" rpy="0 0 0"/>
      <geometry>
        <capsule length="0.3" radius="0.03"/>
      </geometry>
      <material name="white"/>
    </visual>
    <collision>
     <origin xyz="0 0 0.15" rpy="0 0 0"/>
      <geometry>
        <capsule length="0.3" radius="0.03"/>
      </geometry>
    </collision>
  </link>

  <link name="linkEE">
    <visual>
     <origin xyz="0 0 0" rpy="0 0 0"/>
      <geometry>
        <sphere radius="0.04"/>
      </geometry>
      <material name="green"/>
    </visual>
    <collision>
          <origin xyz="0 0 0" rpy="0 0 0"/>
      <geometry>
        <sphere radius="0.04"/>
      </geometry>
      <material name="green"/>
    </collision>
  </link>

  <!-- Define joints -->
  <joint name="joint1" type="revolute">
    <parent link="base_link"/>
    <child link="link1"/>
    <origin xyz="0 0 0" rpy="0 0 0"/>
    <axis xyz="0 0 1"/>
    <limit effort="100" lower="-3.1415" upper="1.5707" velocity="10"/>
  </joint>

  <joint name="joint2" type="revolute">
    <parent link="link1"/>
    <child link="link2"/>
    <origin xyz="0 0 0.5" rpy="0 0 0"/>
    <axis xyz="1 0 0"/>
    <limit effort="100" lower="-1.5707" upper="1.5707" velocity="10"/>
  </joint>

  <joint name="joint3" type="revolute">
    <parent link="link2"/>
    <child link="link3"/>
    <origin xyz="0 0 0.4" rpy="0 0 0"/>
    <axis xyz="1 0 0"/>
    <limit effort="100" lower="-1.5707" upper="1.5707" velocity="10"/>
  </joint>

  <joint name="jointEE" type="fixed">
    <parent link="link3"/>
    <child link="linkEE"/>
    <origin xyz="0 0 0.3" rpy="0 0 0"/>
    <axis xyz="0 0 1"/>
  </joint>

</robot>
